<?xml version="1.0"?>
<robot xmlns:xacro="http://www.ros.org/wiki/xacro" name="cyton1500_gripper">

	<!--  gripper  stuff  -->
  <joint name="gripper_joint" type="prismatic">
    <parent link="wrist_roll"/>
    <child link="gripper_finger1"/>
    <origin rpy="0 0 0" xyz="-0.01331 0.00485 0.077225"/>
    <limit effort="100.0" lower="-0.008" upper="0.008" velocity="1.0"/>
    <axis xyz="1 0 0"/>
  </joint>
  <link name="gripper_finger1">
    <visual>
      <origin rpy="0 0 0" xyz="0 0 0"/>
      <geometry>
        <mesh filename="package://cyton_gamma_1500_description/meshes/gripper_finger1.dae"/>
      </geometry>
    </visual>
    <collision>
      <origin xyz="-0.005 0.01 0.02"/>
      <geometry>
        <box size="0.015 0.0229 0.03"/>
      </geometry>
    </collision>
    <inertial>
      <mass value="1.0"/>
      <origin rpy="0 0 0" xyz="0 0 0"/>
      <inertia ixx=".0027" ixy="0" ixz="0" iyy=".0027" iyz="0" izz=".0027"/>
    </inertial>
  </link>
  <transmission name="tran8">
    <type>transmission_interface/SimpleTransmission</type>
    <joint name="gripper_joint">
      <hardwareInterface>PositionJointInterface</hardwareInterface>
    </joint>
    <actuator name="motor8">
      <hardwareInterface>PositionJointInterface</hardwareInterface>
    </actuator>
  </transmission>
  <joint name="gripper_joint2" type="prismatic">
    <parent link="wrist_roll"/>
    <child link="gripper_finger2"/>
    <origin rpy="0 0 0" xyz="0.0098 0.00485 0.077225"/>
    <limit effort="100.0" lower="-0.008" upper="0.008" velocity="1.0"/>
    <mimic joint="gripper_joint" multiplier="-1"/>
    <axis xyz="1 0 0"/>
  </joint>
  <link name="gripper_finger2">
    <visual>
      <origin rpy="0 0 0" xyz="0 0 0"/>
      <geometry>
        <mesh filename="package://cyton_gamma_1500_description/meshes/gripper_finger2.dae"/>
      </geometry>
    </visual>
    <collision>
      <origin xyz="0.005 0.01 0.02"/>
      <geometry>
        <box size="0.015 0.0229 0.03"/>
      </geometry>
    </collision>
    <inertial>
      <mass value="1.0"/>
      <origin rpy="0 0 0" xyz="0 0 0"/>
      <inertia ixx=".0027" ixy="0" ixz="0" iyy=".0027" iyz="0" izz=".0027"/>
    </inertial>
  </link>
  <transmission name="tran9">
    <type>transmission_interface/SimpleTransmission</type>
    <joint name="gripper_joint2">
      <hardwareInterface>PositionJointInterface</hardwareInterface>
    </joint>
    <actuator name="motor9">
      <hardwareInterface>PositionJointInterface</hardwareInterface>
    </actuator>
  </transmission>
		
</robot>


